2025-01-15 15:58:34,953 - tests_12_4 - WARNING - test_run: 27 - Неверный тип данных для объекта Runner
Traceback (most recent call last):
  File "D:\myexperiences\urban_university_python\module_12\tests_12_4.py", line 21, in test_run
    runner = Runner(555)
             ^^^^^^^^^^^
  File "D:\myexperiences\urban_university_python\module_12\rt_with_exceptions.py", line 6, in __init__
    raise TypeError(f'Имя может быть только строкой, передано {type(name).__name__}')
TypeError: Имя может быть только строкой, передано int
2025-01-15 15:58:34,954 - tests_12_4 - WARNING - test_walk: 17 - Неверная скорость для Runner
Traceback (most recent call last):
  File "D:\myexperiences\urban_university_python\module_12\tests_12_4.py", line 11, in test_walk
    runner = Runner('red', -5)
             ^^^^^^^^^^^^^^^^^
  File "D:\myexperiences\urban_university_python\module_12\rt_with_exceptions.py", line 11, in __init__
    raise ValueError(f'Скорость не может быть отрицательной, сейчас {speed}')
ValueError: Скорость не может быть отрицательной, сейчас -5
